Workbook

Sheet RAB
A1: [NAMA PERUSAHAAN]
A2: [Alamat Perusahaan] | [Telepon] | [Email]
A3: RENCANA ANGGARAN BIAYA (RAB)
A4: Pengembangan Aplikasi PM Cost Control (Project Management & Cost Control)
A6: Nomor: [Nomor Dokumen]
A7: Tanggal: 10 Oktober 2026
A8: Kepada: [Nama Client]
A9: Pekerjaan: Pengembangan aplikasi web PM Cost Control beserta instalasi, pelatihan, dan infrastruktur 1 tahun
A11: No | B11: Uraian Pekerjaan | C11: Pelaksana | D11: Vol | E11: Sat | F11: Harga Satuan (Rp) | G11: Jumlah (Rp)
A12: A | B12: ANALISIS KEBUTUHAN & DESAIN SISTEM
A13: 1 | B13: Analisis kebutuhan & proses bisnis (workshop dengan user) | C13: System Analyst | D13: 5 | E13: OH | F13: =Tarif!$C$5 -> 1500000 | G13: =D13*F13 -> 7500000
A14: 2 | B14: Perancangan alur kerja, pembagian hak akses role & struktur database | C14: System Analyst | D14: 4 | E14: OH | F14: =Tarif!$C$5 -> 1500000 | G14: =D14*F14 -> 6000000
A15: 3 | B15: Desain UI/UX (wireframe & tampilan aplikasi) | C15: UI/UX Designer | D15: 4 | E15: OH | F15: =Tarif!$C$6 -> 1000000 | G15: =D15*F15 -> 4000000
B16: Subtotal A | G16: =SUM(G13:G15) -> 17500000
A17: B | B17: PENGEMBANGAN APLIKASI (PER MODUL)
A18: 1 | B18: Autentikasi, Manajemen User & Hak Akses (6 role) | C18: Full-stack Developer | D18: 4 | E18: OH | F18: =Tarif!$C$7 -> 1250000 | G18: =D18*F18 -> 5000000
A19: 2 | B19: Master Project (data kontrak & status) | C19: Full-stack Developer | D19: 3 | E19: OH | F19: =Tarif!$C$7 -> 1250000 | G19: =D19*F19 -> 3750000
A20: 3 | B20: BOQ & COGS (item pekerjaan, harga material/jasa, revisi) | C20: Full-stack Developer | D20: 8 | E20: OH | F20: =Tarif!$C$7 -> 1250000 | G20: =D20*F20 -> 10000000
A21: 4 | B21: Approval BOQ (pengajuan, review, approve, permintaan revisi) | C21: Full-stack Developer | D21: 4 | E21: OH | F21: =Tarif!$C$7 -> 1250000 | G21: =D21*F21 -> 5000000
A22: 5 | B22: Payment Plan & Pembayaran Pekerjaan | C22: Full-stack Developer | D22: 6 | E22: OH | F22: =Tarif!$C$7 -> 1250000 | G22: =D22*F22 -> 7500000
A23: 6 | B23: Progress Fisik & Earned Value | C23: Full-stack Developer | D23: 3 | E23: OH | F23: =Tarif!$C$7 -> 1250000 | G23: =D23*F23 -> 3750000
A24: 7 | B24: Pengadaan: BMHP, Aset & Sewa Alat (pengajuan s/d pembayaran) | C24: Full-stack Developer | D24: 8 | E24: OH | F24: =Tarif!$C$7 -> 1250000 | G24: =D24*F24 -> 10000000
A25: 8 | B25: Alokasi Biaya BMHP & Sewa Alat ke Item BOQ | C25: Full-stack Developer | D25: 4 | E25: OH | F25: =Tarif!$C$7 -> 1250000 | G25: =D25*F25 -> 5000000
A26: 9 | B26: Manajemen Aset (master, permintaan, penugasan ke project) | C26: Full-stack Developer | D26: 6 | E26: OH | F26: =Tarif!$C$7 -> 1250000 | G26: =D26*F26 -> 7500000
A27: 10 | B27: Cost Control: Biaya Aktual vs BOQ & Variance | C27: Full-stack Developer | D27: 4 | E27: OH | F27: =Tarif!$C$7 -> 1250000 | G27: =D27*F27 -> 5000000
A28: 11 | B28: Penagihan Client (termin, invoice, pembayaran client, piutang) | C28: Full-stack Developer | D28: 8 | E28: OH | F28: =Tarif!$C$7 -> 1250000 | G28: =D28*F28 -> 10000000
A29: 12 | B29: Dokumen Project (versi, review client, revisi, approval) | C29: Full-stack Developer | D29: 7 | E29: OH | F29: =Tarif!$C$7 -> 1250000 | G29: =D29*F29 -> 8750000
... A32: 15 | B32: Laporan per Project (8 jenis laporan, export CSV, cetak/PDF) | C32: Full-stack Developer | D32: 5 | E32: OH | F32: =Tarif!$C$7 -> 1250000 | G32: =D32*F32 -> 6250000
B33: Subtotal B | G33: =SUM(G18:G32) -> 97500000
A34: C | B34: INSTALASI & DEPLOYMENT
A35: 1 | B35: Setup server: web server, PHP, database, SSL, keamanan dasar | C35: DevOps Engineer | D35: 2 | E35: OH | F35: =Tarif!$C$8 -> 1250000 | G35: =D35*F35 -> 2500000
A36: 2 | B36: Deployment aplikasi, migrasi database & input data awal (user, master) | C36: DevOps Engineer | D36: 2 | E36: OH | F36: =Tarif!$C$8 -> 1250000 | G36: =D36*F36 -> 2500000
B37: Subtotal C | G37: =SUM(G35:G36) -> 5000000
A38: D | B38: PELATIHAN & DOKUMENTASI
A39: 1 | B39: Pelatihan pengguna per role (6 role) | C39: Trainer | D39: 2 | E39: OH | F39: =Tarif!$C$9 -> 1000000 | G39: =D39*F39 -> 2000000
A40: 2 | B40: Buku panduan pengguna (user manual) | C40: Technical Writer | D40: 3 | E40: OH | F40: =Tarif!$C$10 -> 1000000 | G40: =D40*F40 -> 3000000
A41: 3 | B41: Dokumentasi teknis & serah terima source code | C41: Technical Writer | D41: 2 | E41: OH | F41: =Tarif!$C$10 -> 1000000 | G41: =D41*F41 -> 2000000
B42: Subtotal D | G42: =SUM(G39:G41) -> 7000000
A43: E | B43: INFRASTRUKTUR (1 TAHUN)
A44: 1 | B44: Cloud server / VPS (2 vCPU, 4 GB RAM, 80 GB SSD) | C44: Penyedia cloud | D44: 12 | E44: Bulan | F44: 350000 | G44: =D44*F44 -> 4200000
...

Sheet Rincian Fitur
A1: LAMPIRAN: RINCIAN FITUR APLIKASI PM COST CONTROL
A2: Lingkup pekerjaan bagian B (Pengembangan Aplikasi) pada RAB.
A4: No | B4: Modul | C4: Rincian Fitur | D4: Estimasi (OH)
A5: 1 | B5: Autentikasi, Manajemen User & Hak Akses (6 role) | C5: - Login, logout, reset password, profil user - 6 role: Superadmin, Project Admin, BOQ & Cost Control, Approver, Finance, Project Site - Hak akses per fitur (permission) sesuai role - Pengaturan role user oleh Superadmin | D5: 4
A6: 2 | B6: Master Project (data kontrak & status) | C6: - Data project, client, nomor & nilai kontrak, tanggal mulai dan target selesai - Status project - Peringatan kontrak akan berakhir / sudah lewat - Hapus project (khusus Superadmin) | D6: 3
A7: 3 | B7: BOQ & COGS (item pekerjaan, harga material/jasa, revisi) | C7: - Penyusunan BOQ per kelompok COGS dan item pekerjaan - Harga satuan terpisah Material dan Jasa - Import item COGS dari template - Revisi BOQ beserta riwayat perubahan | D7: 8
A8: 4 | B8: Approval BOQ (pengajuan, review, approve, permintaan revisi) | C8: - Pengajuan BOQ dan antrian approval - Review, approve, atau minta revisi dengan catatan | D8: 4
A9: 5 | B9: Payment Plan & Pembayaran Pekerjaan | C9: - Rencana pembayaran yang terhubung ke item BOQ - Proses pembayaran: tanggal, metode, nomor referensi - Void pembayaran dengan alasan, alasan overrun | D9: 6
A10: 6 | B10: Progress Fisik & Earned Value | C10: - Update progress per item pekerjaan - Bobot item, progress COGS / BOQ / project - Nilai pekerjaan selesai (earned value) | D10: 3
A11: 7 | B11: Pengadaan: BMHP, Aset & Sewa Alat (pengajuan s/d pembayaran) | C11: - Permintaan BMHP, Aset, dan Sewa Alat per project - Alur Draft -> Diajukan -> Disetujui (Approver) -> Dibayar (Finance), kembalikan ke draft, pembatalan - Pencatatan pembayaran, nomor invoice, upload bukti bayar - Import daftar BMHP dari file CSV (template disediakan) - Aset otomatis tercatat setelah pembelian dibayar | D11: 8
A12: 8 | B12: Alokasi Biaya BMHP & Sewa Alat ke Item BOQ | C12: - Alokasi nilai BMHP dan sewa alat ke item BOQ - Alokasi dapat diubah, langsung menjadi biaya aktual item | D12: 4
A13: 9 | B13: Manajemen Aset (master, permintaan, penugasan ke project) | C13: - Master aset: kode, kategori, merk, model, kondisi - Permintaan aset, import & export data aset - Penugasan aset ke project dan pengembalian | D13: 6
A14: 10 | B14: Cost Control: Biaya Aktual vs BOQ & Variance | C14: - Biaya aktual = BMHP + Sewa Alat + Pembayaran pekerjaan - Perbandingan dengan nilai BOQ per item, COGS, dan project - Status Normal / Warning (>= 90%) / Over Budget | D14: 4
A15: 11 | B15: Penagihan Client (termin, invoice, pembayaran client, piutang) | C15: - Termin pembayaran (persentase / nilai tetap) dari nilai kontrak - Syarat penagihan: progress fisik, tanggal, milestone, manual - Pemberitahuan "lakukan penagihan" saat syarat termin tercapai - Penagihan: draft, ajukan, kirim invoice, batal - Pencatatan pembayaran client, piutang, dan jatuh tempo | D15: 8
A16: 12 | B16: Dokumen Project (versi, review client, revisi, approval) | C16: - Jenis dokumen dan upload dokumen dengan versi - Alur: submit, review client, revisi, resubmit, approve, batal - Riwayat status, durasi menunggu, monitoring dokumen tertunda | D16: 7
... A19: 15 | B19: Laporan per Project (8 jenis laporan, export CSV, cetak/PDF) | C19: - Ringkasan, Progress, Permintaan & Pembelian, Biaya vs BOQ, Pembayaran, Penagihan, Aset, Dokumen - Filter periode, export CSV, cetak / simpan PDF | D19: 5

Sheet Tarif
A1: TARIF TENAGA KERJA (PER ORANG-HARI)
A2: Ubah tarif pada kolom C; harga satuan di lembar RAB akan ikut berubah.
A4: No | B4: Pelaksana | C4: Tarif / OH (Rp) | D4: Lingkup
A5: 1 | B5: System Analyst | C5: 1500000 | D5: Analisis proses bisnis, alur kerja, hak akses, desain database
A6: 2 | B6: UI/UX Designer | C6: 1000000 | D6: Wireframe dan desain tampilan aplikasi
A7: 3 | B7: Full-stack Developer | C7: 1250000 | D7: Pemrograman backend Laravel & frontend, termasuk pengujian internal
A8: 4 | B8: DevOps Engineer | C8: 1250000 | D8: Setup server, keamanan, deployment
A9: 5 | B9: Trainer | C9: 1000000 | D9: Pelatihan pengguna per role
A10: 6 | B10: Technical Writer | C10: 1000000 | D10: Penyusunan buku panduan & dokumentasi teknis
A12: OH = Orang-Hari (1 orang bekerja 8 jam).
